Workbook
Name FtrArmr: '[1]1-Hull'!$AA$17
Name FtrArmr: '[2]1-Hull'!$AA$17
Name FtrArmr: '1-Hull'!$AA$17
Name HullConfig: #REF!
Name Tech_Level: '[1]Ship Info'!$F$2
Name Tech_Level: '[2]Ship Info'!$F$2
Name Tech_Level: 'Ship Info'!$F$2
Name TL: '[1]Ship Info'!$F$2
Name TL: '[2]Ship Info'!$F$2
Name TL: 'Ship Info'!$F$2
Name Tonnage: '[1]1-Hull'!$B$4
Name Tonnage: '[2]1-Hull'!$B$4
Name Tonnage: '1-Hull'!$B$4

Sheet Instructions
A1: Version 2026, January 22
A3: This is a ship designer for a certain version of a certain D6 RPG game made popular in the 1970's using the current HG stats.
A5: The process has been broken up into several steps, and separated into tabs on the bottom.
A7: It is recommended that you copy the blank to another file, such as the name of the ship or class prior to entering any data, so that you can upgrade or save designs for later.
A9: Start with Ship Info. (Green Tab)
A10: There are now three modes on this tab that will determine how the rest of the sheet works. Ship, Station and Module. I recommend saving a copy of this file as a blank for each mode.
A12: This spreadsheet uses "," to separate 000's and "." to indicate decimals. If you get an #ARG! Error, check your EXCEL settings.
A14: Some ship's systems can be modded. These are optional rules. Clear their use with your game master first.
A16: The Summary, Record Sheet and the SSD automatically fill out based on your choices. These can be printed to a printer or as PDF's for later use.
A17: The SSD has room for 3000 damage boxes. These will scale by a factor of 10 or 100 with the hull points. Hatched boxes indicate the 10% critical threshhold.
A18: There are two sets of counters on the right that allow you to count partial boxes. The boxes and counters will be greyed out until applicable.
A19: The Capital Ship SSD is located after the Cargo Tab. It provides larger print and 10,560 boxes, with a maximum scale of x1000 and partial box counters going to the hundreds. Warning, it is slow.
... A33: Arkathan -October, 2021

Sheet Jank Build Info
A1: CLUSTER TRUCK BUILDER - Material Inventory & Construction
A3: MATERIAL INVENTORY
A4: Material Type | B4: Units Available | C4: Unit Cost (MCr) | D4: Total Value (MCr) | E4: Unit Weight (Tons) | F4: Total Weight
A5: Structural | B5: 0 | C5: 0.01 | D5: =B5*C5 -> 0 | E5: 0.1 | F5: =E5*B5 -> 0
A6: Technical | B6: 0 | C6: 0.025 | D6: =B6*C6 -> 0 | E6: 0.01 | F6: =E6*B6 -> 0
A7: Outfitting | B7: 0 | C7: 0.001 | D7: =B7*C7 -> 0 | E7: 0.1 | F7: =E7*B7 -> 0
A9: COMPONENT CONSTRUCTION
A10: Component Name | B10: Component Type | C10: Tonnage | D10: Current Quality | E10: Target Quality | F10: Structural Req | G10: Technical Req | H10: Outfitting Req | I10: Labor (Shifts) | K10: Crude
K11: Beyond Janky
K12: Janky
K13: Basic
K14: Standard
K15: Improved
A16: LABOR & FACILITY | K16: High Quality
A17: Facility Type | B17: Crew Only | C17: Basic Rig | D17: Full Cradle
A18: Shifts/Ton Formula | B18: 4D+4 | C18: 3D+3 | D18: 2D+2
A19: Shifts Range: (x6 for hours) | B19: (low 8, avg 18, high 28) | C19: (low 6, avg 13.5, high 21) | D19: (low 4, avg 9, high 14)
A21: QUALITY SYSTEM
A22: Quality Level | B22: Performance % | C22: DM Modifier | D22: Materials to Upgrade
A23: Busted | B23: 0 | C23: Non-Functional | D23: 0.1
A24: Crude | B24: 0.15 | C24: -4 | D24: 0.25 | H24: 0.1 | I24: 0.3 | J24: 0.6 | K24: 0.8
A25: Beyond Janky | B25: 0.4 | C25: -3 | D25: 0.5 | H25: 0.11 | I25: 0.31 | J25: 0.61 | K25: 0.81
A26: Janky | B26: 0.65 | C26: -2 | D26: 0.75 | H26: 0.12 | I26: 0.32 | J26: 0.62 | K26: 0.82
A27: Basic | B27: 0.85 | C27: -1 | D27: 1 | H27: 0.13 | I27: 0.33 | J27: 0.63 | K27: 0.83
A28: Standard | B28: 1 | C28: 0 | D28: 1.5 | H28: 0.14 | I28: 0.34 | J28: 0.64 | K28: 0.84
A29: Improved | B29: 1.2 | C29: 1 | D29: 2.5 | H29: 0.15 | I29: 0.35 | J29: 0.65 | K29: 0.85
A30: High-Quality | B30: 1.5 | C30: 2 | H30: 0.16 | I30: 0.36 | J30: 0.66 | K30: 0.86
H31: 0.17 | I31: 0.37 | J31: 0.67 | K31: 0.87
A32: Performance Mode: | B32: Reduce Actual Performance | H32: 0.18 | I32: 0.38 | J32: 0.68 | K32: 0.88
A33: Material Cost Mode: | B33: Average | H33: 0.19 | I33: 0.39 | J33: 0.69 | K33: 0.89
H34: 0.2 | I34: 0.4 | J34: 0.7 | K34: 0.9
I35: 0.41
A36: MATERIAL REQUIREMENTS - STRUCTURAL | I36: 0.42
A37: Component Type | B37: Example | C37: Requirement Construction (Ton) | D37: Requirement Upgrade (Ton) | I37: 0.43
A38: Structural | B38: Hull and Bulkheads | C38: 3D | D38: 1D | I38: 0.44
A39: Utility | B39: Cabins | C39: 3D | D39: 1D | I39: 0.45
A40: Control | B40: Bridge | C40: 1D | D40: D3 | I40: 0.46
A41: Machinery | B41: Power Plant | C41: 8D | D41: 2D | I41: 0.47
A42: Drives | B42: M-Drive | C42: 12D | D42: 4D | I42: 0.48
I43: 0.49
...

Sheet Cluster Truck Builder
A1: CLUSTER TRUCK: Salvage & Scrap Ship Construction System
A2: Mongoose Traveller 2e - Estuary Cluster Rules
A4: SECTION 1: MATERIAL INVENTORY & COSTS
A5: Material Type | B5: Units on Hand | C5: Cost per Unit (Cr) | D5: Weight per Unit (tons) | E5: Total Value (Cr)
A6: Structural | B6: 0 | C6: 10000 | D6: 0.1 | E6: =B6*C6 -> 0
A7: Technical | B7: 0 | C7: 25000 | D7: 0.01 | E7: =B7*C7 -> 0
A8: Outfitting | B8: 0 | C8: 1000 | D8: 0.1 | E8: =B8*C8 -> 0
A9: TOTAL INVENTORY VALUE | E9: =SUM(E6:E8) -> 0
A11: SECTION 2: COMPONENT CONSTRUCTION CALCULATOR | M11: Structural | O11: Crude | Q11: Build
A12: Component Type: | B12: Structural | D12: (Dropdown: Structural/Utility/Control/Machinery/Drives) | M12: Utility | O12: Beyond Janky | Q12: Upgrade
A13: Tonnage to Build: | B13: 10 | D13: tons | M13: Control | O13: Janky
A14: Target Quality: | B14: Janky | D14: (Dropdown: Crude/Beyond Janky/Janky/Basic/Standard) | M14: Machinery | O14: Basic
A15: Build or Upgrade | B15: Build | M15: Drives | O15: Standard
O16: Improved
A17: MATERIALS REQUIRED: | B17: Low | C17: Median | D17: High | O17: High Quality
A18: Structural units needed: | B18: =B12*10 -> #VALUE! | C18: =C12*10 -> 0 | D18: =D12*10 -> #VALUE!
A19: Technical units needed: | B19: =B12*5 -> #VALUE! | C19: =C12*5 -> 0 | D19: =D12*5 -> #VALUE!
A20: Outfitting units needed: | B20: =B12*2 -> #VALUE! | C20: =C12*2 -> 0 | D20: =D12*2 -> #VALUE!
A21: Total Material Cost: | B21: =(B18*10000)+(B19*25000)+(B20*1000) -> #VALUE! | C21: =(C18*10000)+(C19*25000)+(C20*1000) -> 0 | D21: =(D18*10000)+(D19*25000)+(D20*1000) -> #VALUE!
A22: Have sufficient materials? | B22: Check inventory above
A24: SECTION 3: LABOR & FACILITY REQUIREMENTS | M24: Crew Only
A25: Construction Facility: | B25: Basic Rig | D25: (Crew-Only/Makeshift Frame/Basic Rig/Full Cradle) | M25: Makeshift Frame
A26: Shifts Required: | B26: =(3*3+3)*10 -> 120 | D26: shifts (based on facility & tonnage) | M26: Basic Rig
A27: Crew Size: | B27: 5 | D27: workers | M27: Full Cradle
A28: Days to Complete: | B28: =B26/(B27*2) -> 12 | D28: days (assumes 2 shifts/day)
A29: Engineer Skill Level: | B29: 2 | D29: DM for quality roll
A31: SECTION 4: QUALITY ROLLER & RESULTS
A32: Roll 2D: | B32: 7 | D32: (Enter your 2D6 roll result)
A33: Quality DM: | B33: =B25 -> Basic Rig | D33: (From Engineer + Facility - TL difference)
A34: Final Result: | B34: =B32+B33 -> #VALUE!
A35: Component Quality: | B35: Janky | D35: (Lookup from quality table)
A36: Performance %: | B36: 65% | D36: (10-150% based on quality)
A37: DM Applied: | B37: -2 | D37: (-4 to +2 based on quality)
A39: SECTION 5: SALVAGE QUALITY DETERMINATION
A40: Salvage Source: | B40: Wreck | D40: (Wreck/Derelict/Scrap Yard)
A41: Salvage Roll (2D): | B41: 7
A42: Component Condition: | B42: Beyond Janky | D42: (Table lookup based on source + roll)
A43: Can Upgrade To: | B43: Janky | D43: (Next quality level)
A45: SECTION 6: UPGRADE COST CALCULATOR
A46: Current Quality: | B46: Janky
...

Sheet Summary
A1: ="Class: "&'Ship Info'!B1&IF(OR('Ship Info'!B2=0,'Ship Info'!B2)="",""," - "&'Ship Info'!B2) -> Class: - | C1: =Tonnage -> 100 | D1: =" Tons "&I1&" TL "&Tech_Level -> Tons Ship TL 12 | I1: =IF(AND('Ship Info'!F7,'Ship Info'!I6="Yes"),"Pod",'Ship Info'!E6) -> Ship | K1: =""
A2: Components | C2: Tons | D2: Cost (Cr) | E2: 1 | F2: 1 | G2: Hull | H2: ='1-Hull'!$B$6&IF('1-Hull'!$B$7="","","-"&'1-Hull'!$B$7)&IF('1-Hull'!$B$6="Streamlined","",", "&'1-Hull'!$B$8)&", "&IF('1-Hull'!$D$5="Yes",""," Non-Gravitic ")&'1-Hull'!$D$6&": "&TEXT('1-Hull'!$D$7,"#,###") -> Standard, Partial, Standard Hull: 40 | I2: ="" | J2: ='1-Hull'!F6 -> 5000000 | K2: ='Ship Info'!C33 -> On
A3: Hull | B3: =H2 -> Standard, Partial, Standard Hull: 40 | D3: =J2 -> 5000000 | E3: =IF(H3="",E2,E2+1) -> 1 | F3: =IF(E3=E2,"",E3) | H3: =IF('1-Hull'!$C$9="No","","Military Hull") | I3: 0 | J3: ='1-Hull'!$F$9 -> 0 | K3: 1
A4: =IF(INDEX(F:J,MATCH(2,F:F,0),2)=0,"",INDEX(F:J,MATCH(2,F:F,0),2)) -> Power Plant | B4: =INDEX(F:J,MATCH(2,F:F,0),3) -> TL 12 Fusion Output: 20 | C4: =INDEX(F:J,MATCH(2,F:F,0),4) -> 1.3333333 | D4: =INDEX(F:J,MATCH(2,F:F,0),5) -> 1333333.3 | E4: =IF(H4="",E3,E3+1) -> 1 | F4: =IF(E4=E3,"",E4) | H4: =IF('1-Hull'!C36=0,"","Secondary Hull "&'1-Hull'!C36&" Tons, "&'1-Hull'!D38&" "&INDEX('1-Hull'!S2:T8,MATCH('1-Hull'!D38,'1-Hull'!S2:S8,0),2)&", "&'1-Hull'!D39) | K4: =IF(B4="","",IF(A4="",K3,K3+1)) -> 2
A5: =IF(INDEX(F:J,MATCH(3,F:F,0),2)=0,"",INDEX(F:J,MATCH(3,F:F,0),2)) -> Fuel | B5: =INDEX(F:J,MATCH(3,F:F,0),3) -> 4 Weeks of Operation* | C5: =INDEX(F:J,MATCH(3,F:F,0),4) -> 0.13333333 | D5: =INDEX(F:J,MATCH(3,F:F,0),5) | E5: =IF(H5="",E4,E4+1) -> 1 | F5: =IF(E5=E4,"",E5) | H5: =IF(J5=0,"",'1-Hull'!B28&": "&'1-Hull'!B29) | I5: ='1-Hull'!H28 -> 0 | J5: ='1-Hull'!F28 -> 0 | K5: =IF(B5="","",IF(A5="",K4,K4+1)) -> 3
A6: =IF(MAX(F:F)<4,"",IF(INDEX(F:J,MATCH(4,F:F,0),2)=0,"",INDEX(F:J,MATCH(4,F:F,0),2))) -> Bridge | B6: =IF(MAX(F:F)<4,"",INDEX(F:J,MATCH(4,F:F,0),3)) -> Standard Bridge | C6: =IF(MAX(F:F)<4,"",INDEX(F:J,MATCH(4,F:F,0),4)) -> 6 | D6: =IF(MAX(F:F)<4,"",INDEX(F:J,MATCH(4,F:F,0),5)) -> 500000 | E6: =IF(H6="",E5,E5+1) -> 1 | F6: =IF(E6=E5,"",E6) | H6: =IF('1-Hull'!A$14<>'1-Hull'!S$25,IF('1-Hull'!C36=0,"","Combined Hull: ")&'1-Hull'!S$26,IF('1-Hull'!C36=0,"",IF('1-Hull'!D14='1-Hull'!S25,"","Secondary Hull Only: "&'1-Hull'!S26))) | I6: ='1-Hull'!H$14 -> 0 | J6: ='1-Hull'!F$14 -> 0 | K6: =IF(B6="","",IF(A6="",K5,K5+1)) -> 4
A7: =IF(MAX(F:F)<5,"",IF(INDEX(F:J,MATCH(5,F:F,0),2)=0,"",INDEX(F:J,MATCH(5,F:F,0),2))) -> Computer | B7: =IF(MAX(F:F)<5,"",INDEX(F:J,MATCH(5,F:F,0),3)) -> Comp/ 5 | C7: =IF(MAX(F:F)<5,"",INDEX(F:J,MATCH(5,F:F,0),4)) -> 0 | D7: =IF(MAX(F:F)<5,"",INDEX(F:J,MATCH(5,F:F,0),5)) -> 30000 | E7: =IF(H7="",E6,E6+1) -> 1 | F7: =IF(E7=E6,"",E7) | H7: =IF('1-Hull'!A$15<>'1-Hull'!S$27,IF('1-Hull'!C36=0,"","Combined Hull: ")&'1-Hull'!S$28,IF('1-Hull'!C36=0,"",IF('1-Hull'!D15='1-Hull'!S$27,"","Secondary Hull Only: "&'1-Hull'!S$28))) | I7: ='1-Hull'!H$15 -> 0 | J7: ='1-Hull'!F$15 -> 0 | K7: =IF(B7="","",IF(A7="",K6,K6+1)) -> 5
A8: =IF(MAX(F:F)<6,"",IF(INDEX(F:J,MATCH(6,F:F,0),2)=0,"",INDEX(F:J,MATCH(6,F:F,0),2))) -> Software | B8: =IF(MAX(F:F)<6,"",INDEX(F:J,MATCH(6,F:F,0),3)) -> Library | C8: =IF(MAX(F:F)<6,"",INDEX(F:J,MATCH(6,F:F,0),4)) -> 0 | D8: =IF(MAX(F:F)<6,"",INDEX(F:J,MATCH(6,F:F,0),5)) -> 0 | E8: =IF(H8="",E7,E7+1) -> 1 | F8: =IF(E8=E7,"",E8) | H8: =IF('1-Hull'!A$16<>'1-Hull'!S$29,IF('1-Hull'!C36=0,"","Combined Hull: ")&'1-Hull'!S$30,IF('1-Hull'!C36=0,"",IF('1-Hull'!D$16='1-Hull'!S$29,"","Secondary Hull Only: "&'1-Hull'!S$30))) | I8: ='1-Hull'!H$16 -> 0 | J8: ='1-Hull'!F$16 -> 0 | K8: =IF(B8="","",IF(A8="",K7,K7+1)) -> 6
A9: =IF(MAX(F:F)<7,"",IF(INDEX(F:J,MATCH(7,F:F,0),2)=0,"",INDEX(F:J,MATCH(7,F:F,0),2))) | B9: =IF(MAX(F:F)<7,"",INDEX(F:J,MATCH(7,F:F,0),3)) -> Manoeuvre/0 | C9: =IF(MAX(F:F)<7,"",INDEX(F:J,MATCH(7,F:F,0),4)) -> 0 | D9: =IF(MAX(F:F)<7,"",INDEX(F:J,MATCH(7,F:F,0),5)) -> 0 | E9: =IF(H9="",E8,E8+1) -> 1 | F9: =IF(E9=E8,"",E9) | H9: =IF('1-Hull'!$A$17<>'1-Hull'!$S$48,IF('1-Hull'!C36=0,"","Combined Hull: ")&'1-Hull'!$S$49,IF('1-Hull'!C36=0,"",IF('1-Hull'!D$17='1-Hull'!S$48,"","Secondary Hull Only: "&'1-Hull'!S$49))) | I9: ='1-Hull'!H$17 -> 0 | J9: ='1-Hull'!F$17 -> 0 | K9: =IF(B9="","",IF(A9="",K8,K8+1)) -> 6
A10: =IF(MAX(F:F)<8,"",IF(INDEX(F:J,MATCH(8,F:F,0),2)=0,"",INDEX(F:J,MATCH(8,F:F,0),2))) | B10: =IF(MAX(F:F)<8,"",INDEX(F:J,MATCH(8,F:F,0),3)) -> Intellect | C10: =IF(MAX(F:F)<8,"",INDEX(F:J,MATCH(8,F:F,0),4)) -> 0 | D10: =IF(MAX(F:F)<8,"",INDEX(F:J,MATCH(8,F:F,0),5)) -> 0 | E10: =IF(H10="",E9,E9+1) -> 1 | F10: =IF(E10=E9,"",E10) | H10: =IF('1-Hull'!$A$18<>'1-Hull'!$S$31,IF('1-Hull'!C36=0,"","Combined Hull: ")&'1-Hull'!$A$18,IF('1-Hull'!C36=0,"",IF('1-Hull'!$D$18='1-Hull'!$S$31,"","Secondary Hull Only: "&'1-Hull'!$D$18))) | I10: ='1-Hull'!H$18 -> 0 | J10: ='1-Hull'!F$18 -> 0 | K10: =IF(B10="","",IF(A10="",K9,K9+1)) -> 6
A11: =IF(MAX(F:F)<9,"",IF(INDEX(F:J,MATCH(9,F:F,0),2)=0,"",INDEX(F:J,MATCH(9,F:F,0),2))) -> Sensors | B11: =IF(MAX(F:F)<9,"",INDEX(F:J,MATCH(9,F:F,0),3)) -> Main Sensor Array: Basic x1 | C11: =IF(MAX(F:F)<9,"",INDEX(F:J,MATCH(9,F:F,0),4)) -> 0 | D11: =IF(MAX(F:F)<9,"",INDEX(F:J,MATCH(9,F:F,0),5)) -> 0 | E11: =IF(H11="",E10,E10+1) -> 1 | F11: =IF(E11=E10,"",E11) | H11: =IF('1-Hull'!$A$19<>'1-Hull'!$S$33,IF('1-Hull'!C36=0,"","Combined Hull: ")&'1-Hull'!$A$19,IF('1-Hull'!C36=0,"",IF('1-Hull'!$D$19='1-Hull'!$S$33,"","Secondary Hull Only: "&'1-Hull'!$D$19))) | I11: ='1-Hull'!H$19 -> 0 | J11: ='1-Hull'!F$19 -> 0 | K11: =IF(B11="","",IF(A11="",K10,K10+1)) -> 7
A12: =IF(MAX(F:F)<10,"",IF(INDEX(F:J,MATCH(10,F:F,0),2)=0,"",INDEX(F:J,MATCH(10,F:F,0),2))) -> Systems | B12: =IF(MAX(F:F)<10,"",INDEX(F:J,MATCH(10,F:F,0),3)) -> 1x 2 ton Airlock | C12: =IF(MAX(F:F)<10,"",INDEX(F:J,MATCH(10,F:F,0),4)) -> 0 | D12: =IF(MAX(F:F)<10,"",INDEX(F:J,MATCH(10,F:F,0),5)) -> 0 | E12: =IF(H12="",E11,E11+1) -> 1 | F12: =IF(E12=E11,"",E12) | H12: =IF('1-Hull'!$A$20<>'1-Hull'!$S$38,IF('1-Hull'!C36=0,"","Combined Hull: ")&'1-Hull'!$A$20,IF('1-Hull'!C36=0,"",IF('1-Hull'!$D$20='1-Hull'!$S$38,"","Secondary Hull Only: "&'1-Hull'!$D$20))) | I12: ='1-Hull'!H$20 -> 0 | J12: ='1-Hull'!F$20 -> 0 | K12: =IF(B12="","",IF(A12="",K11,K11+1)) -> 8
A13: =IF(MAX(F:F)<11,"",IF(INDEX(F:J,MATCH(11,F:F,0),2)=0,"",INDEX(F:J,MATCH(11,F:F,0),2))) -> Total | B13: =IF(MAX(F:F)<11,"",INDEX(F:J,MATCH(11,F:F,0),3)) -> 6863333.3 | C13: =IF(MAX(F:F)<11,"",INDEX(F:J,MATCH(11,F:F,0),4)) -> CR | D13: =IF(MAX(F:F)<11,"",INDEX(F:J,MATCH(11,F:F,0),5)) | E13: =IF(H13="",E12,E12+1) -> 1 | F13: =IF(E13=E12,"",E13) | H13: =IF('1-Hull'!$A$21<>'1-Hull'!$S$41,IF('1-Hull'!C36=0,"","Combined Hull: ")&'1-Hull'!$A$21,IF('1-Hull'!C36=0,"",IF('1-Hull'!$D$21='1-Hull'!$S$41,"","Secondary Hull Only: "&'1-Hull'!$D$21))) | I13: ='1-Hull'!H$21 -> 0 | J13: ='1-Hull'!F$21 -> 0 | K13: =IF(B13="","",IF(A13="",K12,K12+1)) -> 9
A14: =IF(MAX(F:F)<12,"",IF(INDEX(F:J,MATCH(12,F:F,0),2)=0,"",INDEX(F:J,MATCH(12,F:F,0),2))) | B14: =IF(MAX(F:F)<12,"",INDEX(F:J,MATCH(12,F:F,0),3)) -> Purchase Price: | C14: =IF(MAX(F:F)<12,"",INDEX(F:J,MATCH(12,F:F,0),4)) | D14: =IF(MAX(F:F)<12,"",INDEX(F:J,MATCH(12,F:F,0),5)) -> 6177000 | E14: =IF(H14="",E13,E13+1) -> 1 | F14: =IF(E14=E13,"",E14) | H14: =IF('1-Hull'!$A$22<>'1-Hull'!$S$46,IF('1-Hull'!C36=0,"","Combined Hull: ")&'1-Hull'!$A$22&": "&'1-Hull'!B22,IF('1-Hull'!C36=0,"",IF('1-Hull'!$D$22='1-Hull'!$S$46,"","Secondary Only: "&'1-Hull'!$D$22&": "&INDEX('1-Hull'!S46:AA47,MATCH('1-Hull'!D22,'1-Hull'!S46:S47,0),9)))) | I14: ='1-Hull'!H$22 -> 0 | J14: ='1-Hull'!F$22 -> 0 | K14: =IF(B14="","",IF(A14="",K13,K13+1)) -> 9
A15: =IF(MAX(F:F)<13,"",IF(INDEX(F:J,MATCH(13,F:F,0),2)=0,"",INDEX(F:J,MATCH(13,F:F,0),2))) -> Ship Expenses | B15: =IF(MAX(F:F)<13,"",INDEX(F:J,MATCH(13,F:F,0),3)) -> Mortgage: | C15: =IF(MAX(F:F)<13,"",INDEX(F:J,MATCH(13,F:F,0),4)) | D15: =IF(MAX(F:F)<13,"",INDEX(F:J,MATCH(13,F:F,0),5)) -> 25737.5 | E15: =IF(H15="",E14,E14+1) -> 1 | F15: =IF(E15=E14,"",E15) | H15: =IF('1-Hull'!$A$23<>'1-Hull'!$S$50,IF('1-Hull'!C36=0,"","Combined Hull: ")&'1-Hull'!$A$23&": "&'1-Hull'!B23,IF('1-Hull'!C36=0,"",IF('1-Hull'!$D$23='1-Hull'!$S$50,"","Secondary Only: "&'1-Hull'!$D$23&": "&INDEX('1-Hull'!S50:AA51,MATCH('1-Hull'!D23,'1-Hull'!S50:S51,0),9)))) | I15: ='1-Hull'!H$23 -> 0 | J15: ='1-Hull'!F$23 -> 0 | K15: =IF(B15="","",IF(A15="",K14,K14+1)) -> 10
A16: =IF(MAX(F:F)<14,"",IF(INDEX(F:J,MATCH(14,F:F,0),2)=0,"",INDEX(F:J,MATCH(14,F:F,0),2))) | B16: =IF(MAX(F:F)<14,"",INDEX(F:J,MATCH(14,F:F,0),3)) -> Maintenance Cost | C16: =IF(MAX(F:F)<14,"",INDEX(F:J,MATCH(14,F:F,0),4)) | D16: =IF(MAX(F:F)<14,"",INDEX(F:J,MATCH(14,F:F,0),5)) -> 515 | E16: =IF(H16="",E15,E15+1) -> 1 | F16: =IF(E16=E15,"",E16) | H16: =IF('1-Hull'!$A$24='1-Hull'!$S$43,"",'1-Hull'!$A$24&" "&'1-Hull'!$D$24&"% Coverage Power:"&'1-Hull'!$K24*-1) | I16: ='1-Hull'!H$24 -> 0 | J16: ='1-Hull'!F$24 -> 0 | K16: =IF(B16="","",IF(A16="",K15,K15+1)) -> 10
A17: =IF(MAX(F:F)<15,"",IF(INDEX(F:J,MATCH(15,F:F,0),2)=0,"",INDEX(F:J,MATCH(15,F:F,0),2))) | B17: =IF(MAX(F:F)<15,"",INDEX(F:J,MATCH(15,F:F,0),3)) -> Life Support: | C17: =IF(MAX(F:F)<15,"",INDEX(F:J,MATCH(15,F:F,0),4)) | D17: =IF(MAX(F:F)<15,"",INDEX(F:J,MATCH(15,F:F,0),5)) -> 0 | E17: =IF(H17="",E16,E16+1) -> 1 | F17: =IF(E17=E16,"",E17) | H17: =IF('1-Hull'!$C$32=0,"",TEXT('1-Hull'!$C$32,"#,##0.00")&" Tons of Modular Sections") | I17: 0 | J17: =SUM('1-Hull'!F$32:F$34) -> 0 | K17: =IF(B17="","",IF(A17="",K16,K16+1)) -> 10
A18: =IF(MAX(F:F)<16,"",IF(INDEX(F:J,MATCH(16,F:F,0),2)=0,"",INDEX(F:J,MATCH(16,F:F,0),2))) | B18: =IF(MAX(F:F)<16,"",INDEX(F:J,MATCH(16,F:F,0),3)) -> Crew Salaries: | C18: =IF(MAX(F:F)<16,"",INDEX(F:J,MATCH(16,F:F,0),4)) | D18: =IF(MAX(F:F)<16,"",INDEX(F:J,MATCH(16,F:F,0),5)) -> 19000 | E18: =IF(H18="",E17,E17+1) -> 1 | F18: =IF(E18=E17,"",E18) | H18: =IF('1-Hull'!$C$36=0,"",TEXT('1-Hull'!$C$36,"#,##0.00")&" Dtons of Breakaway Hull(s)") | I18: ='1-Hull'!H$36 -> 0 | J18: ='1-Hull'!F$36 -> 0 | K18: =IF(B18="","",IF(A18="",K17,K17+1)) -> 10
A19: =IF(MAX(F:F)<17,"",IF(INDEX(F:J,MATCH(17,F:F,0),2)=0,"",INDEX(F:J,MATCH(17,F:F,0),2))) | B19: =IF(MAX(F:F)<17,"",INDEX(F:J,MATCH(17,F:F,0),3)) -> Fuel: | C19: =IF(MAX(F:F)<17,"",INDEX(F:J,MATCH(17,F:F,0),4)) | D19: =IF(MAX(F:F)<17,"",INDEX(F:J,MATCH(17,F:F,0),5)) -> 0 | E19: =IF(H19="",E18,E18+1) -> 1 | F19: =IF(E19=E18,"",E19) | H19: =IF('1-Hull'!$A$44='1-Hull'!$AC$58,"",'1-Hull'!$A$43&": "&TEXT('1-Hull'!$C$43,"#,##0.00")&" Dton Outer Hull") | I19: ='1-Hull'!H$43 -> 0 | J19: ='1-Hull'!F$46 -> 0 | K19: =IF(B19="","",IF(A19="",K18,K18+1)) -> 10
A20: =IF(MAX(F:F)<18,"",IF(INDEX(F:J,MATCH(18,F:F,0),2)=0,"",INDEX(F:J,MATCH(18,F:F,0),2))) | B20: =IF(MAX(F:F)<18,"",INDEX(F:J,MATCH(18,F:F,0),3)) -> Total Expenses: | C20: =IF(MAX(F:F)<18,"",INDEX(F:J,MATCH(18,F:F,0),4)) | D20: =IF(MAX(F:F)<18,"",INDEX(F:J,MATCH(18,F:F,0),5)) -> 45252.5 | E20: =IF(H20="",E19,E19+1) -> 1 | F20: =IF(E20=E19,"",E20) | H20: =IF('1-Hull'!$C$46=0,"",TEXT('1-Hull'!$C$46,"#,##0.00")&" Dtons of Hamster Cage(s)") | I20: ='1-Hull'!H$46 -> 0 | J20: ='1-Hull'!F$46 -> 0 | K20: =IF(B20="","",IF(A20="",K19,K19+1)) -> 10
A21: =IF(MAX(F:F)<19,"",IF(INDEX(F:J,MATCH(19,F:F,0),2)=0,"",INDEX(F:J,MATCH(19,F:F,0),2))) -> Ship Income | B21: =IF(MAX(F:F)<19,"",INDEX(F:J,MATCH(19,F:F,0),3)) -> Total Income: | C21: =IF(MAX(F:F)<19,"",INDEX(F:J,MATCH(19,F:F,0),4)) | D21: =IF(MAX(F:F)<19,"",INDEX(F:J,MATCH(19,F:F,0),5)) -> 0 | E21: =IF(H21="",E20,E20+1) -> 1 | F21: =IF(E21=E20,"",E21) | G21: =IF(J21=0,"","Armor") | H21: =IF('1-Hull'!$D$11=0,"",IF('1-Hull'!$B$10='1-Hull'!$S$18,"Intrinsic Armor",'1-Hull'!$B$10)&": "&'1-Hull'!$D$11)&IF('1-Hull'!C36=0,"",", 2ry "&IF('1-Hull'!D40='1-Hull'!S18,"",'1-Hull'!D40)&": "&'1-Hull'!G41) | I21: ='1-Hull'!$H$10 -> 0 | J21: ='1-Hull'!$F$10 -> 0 | K21: =IF(B21="","",IF(A21="",K20,K20+1)) -> 11
A22: =IF(MAX(F:F)<20,"",IF(INDEX(F:J,MATCH(20,F:F,0),2)=0,"",INDEX(F:J,MATCH(20,F:F,0),2))) | B22: =IF(MAX(F:F)<20,"",INDEX(F:J,MATCH(20,F:F,0),3)) -> Total Loss: | C22: =IF(MAX(F:F)<20,"",INDEX(F:J,MATCH(20,F:F,0),4)) | D22: =IF(MAX(F:F)<20,"",INDEX(F:J,MATCH(20,F:F,0),5)) -> -45252.5 | E22: =IF(H22="",E21,E21+1) -> 1 | F22: =IF(E22=E21,"",E22) | G22: =IF(H22="","","M-Drive") | H22: =IF('2-Drives'!$B$14='2-Drives'!$S$2,"",'2-Drives'!$S$91&" "&IF('2-Drives'!C11="No",""," @ "&TEXT('2-Drives'!BF25,"#,###")&" Tons")) | I22: =SUM('2-Drives'!H14:H21) -> 0 | J22: =SUM('2-Drives'!F14:F21) -> 0 | K22: =IF(B22="","",IF(A22="",K21,K21+1)) -> 11
A23: =IF(MAX(F:F)<21,"",IF(INDEX(F:J,MATCH(21,F:F,0),2)=0,"",INDEX(F:J,MATCH(21,F:F,0),2))) -> Crew | B23: =IF(MAX(F:F)<21,"",INDEX(F:J,MATCH(21,F:F,0),3)) -> 1x PILOT | C23: =IF(MAX(F:F)<21,"",INDEX(F:J,MATCH(21,F:F,0),4)) | D23: =IF(MAX(F:F)<21,"",INDEX(F:J,MATCH(21,F:F,0),5)) -> 6000 | E23: =IF(H23="",E22,E22+1) -> 1 | F23: =IF(E23=E22,"",E23) | G23: =IF(H23="","",IF(G22="","M-Drive","")) | H23: =IF('2-Drives'!$B$46='2-Drives'!$S$69,"",RIGHT('2-Drives'!$S$92,(LEN('2-Drives'!$S$92)-2))&IF('2-Drives'!C11="No",""," @ "&TEXT('2-Drives'!BF29,"#,###")&" Tons"))&IF('2-Drives'!C50="No","",", SDM") | I23: =SUM('2-Drives'!H46:H54) -> 0 | J23: =SUM('2-Drives'!F46:F54) -> 0 | K23: =IF(B23="","",IF(A23="",K22,K22+1)) -> 12
A24: =IF(MAX(F:F)<22,"",IF(INDEX(F:J,MATCH(22,F:F,0),2)=0,"",INDEX(F:J,MATCH(22,F:F,0),2))) | B24: =IF(MAX(F:F)<22,"",INDEX(F:J,MATCH(22,F:F,0),3)) -> 1x ENGINEER | C24: =IF(MAX(F:F)<22,"",INDEX(F:J,MATCH(22,F:F,0),4)) | D24: =IF(MAX(F:F)<22,"",INDEX(F:J,MATCH(22,F:F,0),5)) -> 4000 | E24: =IF(H24="",E23,E23+1) -> 1 | F24: =IF(E24=E23,"",E24) | H24: =IF('2-Drives'!BJ25="N/A","","Combined M-Drive Rating: "&'2-Drives'!BJ25&"G") | K24: =IF(B24="","",IF(A24="",K23,K23+1)) -> 12
A25: =IF(MAX(F:F)<23,"",IF(INDEX(F:J,MATCH(23,F:F,0),2)=0,"",INDEX(F:J,MATCH(23,F:F,0),2))) | B25: =IF(MAX(F:F)<23,"",INDEX(F:J,MATCH(23,F:F,0),3)) -> 1x MAINTENANCE | C25: =IF(MAX(F:F)<23,"",INDEX(F:J,MATCH(23,F:F,0),4)) | D25: =IF(MAX(F:F)<23,"",INDEX(F:J,MATCH(23,F:F,0),5)) -> 1000 | E25: =IF(H25="",E24,E24+1) -> 1 | F25: =IF(E25=E24,"",E25) | G25: =IF(H25="","","Reaction Drive") | H25: =IF('2-Drives'!$B$23='2-Drives'!$T$12,"",RIGHT('2-Drives'!$S$95,(LEN('2-Drives'!$S$95)-2))&IF('2-Drives'!C11="No",""," @ "&TEXT('2-Drives'!BF26,"#,###")&" Tons")) | I25: =SUM('2-Drives'!H23:H27) -> 0 | J25: =SUM('2-Drives'!F23:F27) -> 0 | K25: =IF(B25="","",IF(A25="",K24,K24+1)) -> 12
A26: =IF(MAX(F:F)<24,"",IF(INDEX(F:J,MATCH(24,F:F,0),2)=0,"",INDEX(F:J,MATCH(24,F:F,0),2))) | B26: =IF(MAX(F:F)<24,"",INDEX(F:J,MATCH(24,F:F,0),3)) -> 1x MEDIC | C26: =IF(MAX(F:F)<24,"",INDEX(F:J,MATCH(24,F:F,0),4)) | D26: =IF(MAX(F:F)<24,"",INDEX(F:J,MATCH(24,F:F,0),5)) -> 4000 | E26: =IF(H26="",E25,E25+1) -> 1 | F26: =IF(E26=E25,"",E26) | G26: =IF(H26="","","High Burn Thruster") | H26: =IF('2-Drives'!$B$37='2-Drives'!$S$14,"",RIGHT('2-Drives'!$S$96,(LEN('2-Drives'!$S$96)-2))&IF('2-Drives'!C11="No",""," @ "&TEXT('2-Drives'!BF30,"#,###")&" Tons")) | I26: =SUM('2-Drives'!H37:H41) -> 0 | J26: =SUM('2-Drives'!F37:F41) -> 0 | K26: =IF(B26="","",IF(A26="",K25,K25+1)) -> 12
A27: =IF(MAX(F:F)<25,"",IF(INDEX(F:J,MATCH(25,F:F,0),2)=0,"",INDEX(F:J,MATCH(25,F:F,0),2))) | B27: =IF(MAX(F:F)<25,"",INDEX(F:J,MATCH(25,F:F,0),3)) -> 1x SENSOP, 1 Sensor Actions per Round | C27: =IF(MAX(F:F)<25,"",INDEX(F:J,MATCH(25,F:F,0),4)) | D27: =IF(MAX(F:F)<25,"",INDEX(F:J,MATCH(25,F:F,0),5)) -> 4000 | E27: =IF(H27="",E26,E26+1) -> 1 | F27: =IF(E27=E26,"",E27) | G27: =IF(H27="","","Sails") | H27: =IF('2-Drives'!$H$44=0,"",'2-Drives'!$S$17 &" Thrust 0") | I27: ='2-Drives'!H44 -> 0 | J27: ='2-Drives'!F44 -> 0 | K27: =IF(B27="","",IF(A27="",K26,K26+1)) -> 12
A28: =IF(MAX(F:F)<26,"",IF(INDEX(F:J,MATCH(26,F:F,0),2)=0,"",INDEX(F:J,MATCH(26,F:F,0),2))) | B28: =IF(MAX(F:F)<26,"",INDEX(F:J,MATCH(26,F:F,0),3)) -> 5 TOTAL SOPHONT CREW | C28: =IF(MAX(F:F)<26,"",INDEX(F:J,MATCH(26,F:F,0),4)) | D28: =IF(MAX(F:F)<26,"",INDEX(F:J,MATCH(26,F:F,0),5)) | E28: =IF(H28="",E27,E27+1) -> 1 | F28: =IF(E28=E27,"",E28) | H28: =IF('2-Drives'!BJ26="N/A","","Combined Reaction Drive Rating: "&'2-Drives'!BJ26&"G") | K28: =IF(B28="","",IF(A28="",K27,K27+1)) -> 12
A29: =IF(MAX(F:F)<27,"",IF(INDEX(F:J,MATCH(27,F:F,0),2)=0,"",INDEX(F:J,MATCH(27,F:F,0),2))) -> Power | B29: =IF(MAX(F:F)<27,"",INDEX(F:J,MATCH(27,F:F,0),3)) -> Power Distribution: Normal (Battle Load) | C29: =IF(MAX(F:F)<27,"",INDEX(F:J,MATCH(27,F:F,0),4)) -> Available: | D29: =IF(MAX(F:F)<27,"",INDEX(F:J,MATCH(27,F:F,0),5)) -> 20 PP | E29: =IF(H29="",E28,E28+1) -> 1 | F29: =IF(E29=E28,"",E29) | G29: =IF(H29="","","FTL") | H29: =IF('2-Drives'!$B$29='2-Drives'!$S$5,"",'2-Drives'!$S$101&IF('2-Drives'!C11="No",""," @ "&TEXT('2-Drives'!BF27,"#,###")&" Tons")) | I29: =SUM('2-Drives'!H29:H34) -> 0 | J29: =SUM('2-Drives'!F29:F34) -> 0 | K29: =IF(B29="","",IF(A29="",K28,K28+1)) -> 13
A30: =IF(MAX(F:F)<28,"",IF(INDEX(F:J,MATCH(28,F:F,0),2)=0,"",INDEX(F:J,MATCH(28,F:F,0),2))) | B30: =IF(MAX(F:F)<28,"",INDEX(F:J,MATCH(28,F:F,0),3)) -> Basic/Hull | C30: =IF(MAX(F:F)<28,"",INDEX(F:J,MATCH(28,F:F,0),4)) | D30: =IF(MAX(F:F)<28,"",INDEX(F:J,MATCH(28,F:F,0),5)) -> 20/ (10) PP | E30: =IF(H30="",E29,E29+1) -> 1 | F30: =IF(E30=E29,"",E30) | G30: =IF(H30="","",IF(G29="","FTL","")) | H30: =IF('2-Drives'!$B$56='2-Drives'!$S$5,"",RIGHT('2-Drives'!$S$102,(LEN('2-Drives'!$S$102)-2))&IF('2-Drives'!C11="No",""," @ "&TEXT('2-Drives'!BF31,"#,###")&" Tons")) | I30: =SUM('2-Drives'!H56:H59) -> 0 | J30: =SUM('2-Drives'!F56:F61) -> 0 | K30: =IF(B30="","",IF(A30="",K29,K29+1)) -> 13
A31: =IF(MAX(F:F)<29,"",IF(INDEX(F:J,MATCH(29,F:F,0),2)=0,"",INDEX(F:J,MATCH(29,F:F,0),2))) | B31: =IF(MAX(F:F)<29,"",INDEX(F:J,MATCH(29,F:F,0),3)) -> Maximum Load (Battle Load) | C31: =IF(MAX(F:F)<29,"",INDEX(F:J,MATCH(29,F:F,0),4)) | D31: =IF(MAX(F:F)<29,"",INDEX(F:J,MATCH(29,F:F,0),5)) -> 20 (10) | E31: =IF(H31="",E30,E30+1) -> 1 | F31: =IF(E31=E30,"",E31) | H31: =IF('2-Drives'!BJ27="N/A","","Combined J-Drive Rating: J"&'2-Drives'!BJ27&IF('2-Drives'!BK27="","",", "&'2-Drives'!BK27)) | K31: =IF(B31="","",IF(A31="",K30,K30+1)) -> 13
A32: =IF(MAX(F:F)<30,"",IF(INDEX(F:J,MATCH(30,F:F,0),2)=0,"",INDEX(F:J,MATCH(30,F:F,0),2))) -> ERROR | B32: =IF(MAX(F:F)<30,"",INDEX(F:J,MATCH(30,F:F,0),3)) -> CREW/STATEROOMS ERROR | C32: =IF(MAX(F:F)<30,"",INDEX(F:J,MATCH(30,F:F,0),4)) | D32: =IF(MAX(F:F)<30,"",INDEX(F:J,MATCH(30,F:F,0),5)) | E32: =IF(H32="",E31,E31+1) -> 2 | F32: =IF(E32=E31,"",E32) -> 2 | G32: =IF(H32="","","Power Plant") -> Power Plant | H32: =IF('3-Pwr Plant'!$D$11=0,"",IF(AND('3-Pwr Plant'!C7='3-Pwr Plant'!S17,'Ship Info'!E6="Module"),"*","")&'3-Pwr Plant'!$B$11&" Output: "&TEXT('3-Pwr Plant'!$D$11+'3-Pwr Plant'!$L$12&" ","#,### ")&'3-Pwr Plant'!$Z$12)&IF(INDEX('3-Pwr Plant'!S2:Y10,MATCH('3-Pwr Plant'!B11,'3-Pwr Plant'!S2:S10,0),7)=0,"",", "&INDEX('3-Pwr Plant'!S2:Y10,MATCH('3-Pwr Plant'!B11,'3-Pwr Plant'!S2:S10,0),7)&" Year Life") -> TL 12 Fusion Output: 20 | I32: =SUM('3-Pwr Plant'!H11:H14) -> 1.3333333 | J32: =SUM('3-Pwr Plant'!F11:F14) -> 1333333.3 | K32: =IF(B32="","",IF(A32="",K31,K31+1)) -> 14
A33: =IF(MAX(F:F)<31,"",IF(INDEX(F:J,MATCH(31,F:F,0),2)=0,"",INDEX(F:J,MATCH(31,F:F,0),2))) | B33: =IF(MAX(F:F)<31,"",INDEX(F:J,MATCH(31,F:F,0),3)) | C33: =IF(MAX(F:F)<31,"",INDEX(F:J,MATCH(31,F:F,0),4)) | D33: =IF(MAX(F:F)<31,"",INDEX(F:J,MATCH(31,F:F,0),5)) | E33: =IF(H33="",E32,E32+1) -> 2 | F33: =IF(E33=E32,"",E33) | H33: =IF(OR('3-Pwr Plant'!$H$15=0,'3-Pwr Plant'!$H$15=""),"","Emergency Power System") | I33: ='3-Pwr Plant'!H15 | J33: ='3-Pwr Plant'!F15 | K33: =IF(B33="","",IF(A33="",K32,K32+1))
A34: =IF(MAX(F:F)<32,"",IF(INDEX(F:J,MATCH(32,F:F,0),2)=0,"",INDEX(F:J,MATCH(32,F:F,0),2))) | B34: =IF(MAX(F:F)<32,"",INDEX(F:J,MATCH(32,F:F,0),3)) | C34: =IF(MAX(F:F)<32,"",INDEX(F:J,MATCH(32,F:F,0),4)) | D34: =IF(MAX(F:F)<32,"",INDEX(F:J,MATCH(32,F:F,0),5)) | E34: =IF(H34="",E33,E33+1) -> 2 | F34: =IF(E34=E33,"",E34) | G34: =IF(G32="",IF(H34="","","Power Plant"),"") | H34: =IF('3-Pwr Plant'!$H$18=0,"",TEXT('3-Pwr Plant'!$D$18,"#,###")&"x "&'3-Pwr Plant'!$C$18&" Batteries - Power: "&TEXT('3-Pwr Plant'!$L$18,"#,###")) | I34: ='3-Pwr Plant'!H18 -> 0 | J34: ='3-Pwr Plant'!F18 -> 0 | K34: =IF(B34="","",IF(A34="",K33,K33+1))
A35: =IF(MAX(F:F)<33,"",IF(INDEX(F:J,MATCH(33,F:F,0),2)=0,"",INDEX(F:J,MATCH(33,F:F,0),2))) | B35: =IF(MAX(F:F)<33,"",INDEX(F:J,MATCH(33,F:F,0),3)) | C35: =IF(MAX(F:F)<33,"",INDEX(F:J,MATCH(33,F:F,0),4)) | D35: =IF(MAX(F:F)<33,"",INDEX(F:J,MATCH(33,F:F,0),5)) | E35: =IF(H35="",E34,E34+1) -> 2 | F35: =IF(E35=E34,"",E35) | G35: =IF(AND(G32="",G34=""),IF(H35="","","Power Plant"),"") | H35: =IF('3-Pwr Plant'!$H$20=0,"",TEXT('3-Pwr Plant'!$D$20,"#,###")&"x Jump Collectors") | I35: ='3-Pwr Plant'!H20 -> 0 | J35: ='3-Pwr Plant'!F20 -> 0 | K35: =IF(B35="","",IF(A35="",K34,K34+1))
A36: =IF(MAX(F:F)<34,"",IF(INDEX(F:J,MATCH(34,F:F,0),2)=0,"",INDEX(F:J,MATCH(34,F:F,0),2))) | B36: =IF(MAX(F:F)<34,"",INDEX(F:J,MATCH(34,F:F,0),3)) | C36: =IF(MAX(F:F)<34,"",INDEX(F:J,MATCH(34,F:F,0),4)) | D36: =IF(MAX(F:F)<34,"",INDEX(F:J,MATCH(34,F:F,0),5)) | E36: =IF(H36="",E35,E35+1) -> 2 | F36: =IF(E36=E35,"",E36) | G36: =IF(AND(G32="",G35="",G34=""),IF(H36="","","Power Plant"),"") | H36: =IF('3-Pwr Plant'!$H$22=0,"",TEXT('3-Pwr Plant'!$D$22,"#,###")&" Units of "&'3-Pwr Plant'!$C$22&" Solar Panels - Power: "&TEXT('3-Pwr Plant'!$L$22,"#,###")) | I36: ='3-Pwr Plant'!H22 -> 0 | J36: ='3-Pwr Plant'!F22 -> 0 | K36: =IF(B36="","",IF(A36="",K35,K35+1))
A37: =IF(MAX(F:F)<35,"",IF(INDEX(F:J,MATCH(35,F:F,0),2)=0,"",INDEX(F:J,MATCH(35,F:F,0),2))) | B37: =IF(MAX(F:F)<35,"",INDEX(F:J,MATCH(35,F:F,0),3)) | C37: =IF(MAX(F:F)<35,"",INDEX(F:J,MATCH(35,F:F,0),4)) | D37: =IF(MAX(F:F)<35,"",INDEX(F:J,MATCH(35,F:F,0),5)) | E37: =IF(H37="",E36,E36+1) -> 2 | F37: =IF(E37=E36,"",E37) | H37: =IF(OR('3-Pwr Plant'!$H$16=0,'3-Pwr Plant'!$H$16=""),"","Armored Bulkheads") | I37: ='3-Pwr Plant'!H16 | J37: ='3-Pwr Plant'!F16 | K37: =IF(B37="","",IF(A37="",K36,K36+1))
A38: =IF(MAX(F:F)<36,"",IF(INDEX(F:J,MATCH(36,F:F,0),2)=0,"",INDEX(F:J,MATCH(36,F:F,0),2))) | B38: =IF(MAX(F:F)<36,"",INDEX(F:J,MATCH(36,F:F,0),3)) | C38: =IF(MAX(F:F)<36,"",INDEX(F:J,MATCH(36,F:F,0),4)) | D38: =IF(MAX(F:F)<36,"",INDEX(F:J,MATCH(36,F:F,0),5)) | E38: =IF(H38="",E37,E37+1) -> 3 | F38: =IF(E38=E37,"",E38) -> 3 | G38: =IF(H38="","","Fuel") -> Fuel | H38: =IF('4-Fuel'!$H$10=0,"",IF('4-Fuel'!$B$9=0,"",'4-Fuel'!$B$9&" "&'4-Fuel'!A9&", ")&'4-Fuel'!$C$10&" Weeks of Operation"&IF('4-Fuel'!$C$5="Yes","*","")&IF('4-Fuel'!$B$8=0,"",", "&"Reaction Hours: "&'4-Fuel'!$B$8)&IF('4-Fuel'!C30='4-Fuel'!T9,"",", F/C Bay")) -> 4 Weeks of Operation* | I38: =SUM('4-Fuel'!H8:H10) -> 0.13333333 | J38: ="" | K38: =IF(B38="","",IF(A38="",K37,K37+1))
A39: =IF(MAX(F:F)<37,"",IF(INDEX(F:J,MATCH(37,F:F,0),2)=0,"",INDEX(F:J,MATCH(37,F:F,0),2))) | B39: =IF(MAX(F:F)<37,"",INDEX(F:J,MATCH(37,F:F,0),3)) | C39: =IF(MAX(F:F)<37,"",INDEX(F:J,MATCH(37,F:F,0),4)) | D39: =IF(MAX(F:F)<37,"",INDEX(F:J,MATCH(37,F:F,0),5)) | E39: =IF(H39="",E38,E38+1) -> 3 | F39: =IF(E39=E38,"",E39) | G39: =IF(G38="",IF(H39="","","Fuel"),"") | H39: =IF('4-Fuel'!$H$11=0,"","Additional Tons of Fuel") | I39: ='4-Fuel'!H11 -> 0 | J39: ="" | K39: =IF(B39="","",IF(A39="",K38,K38+1))
A40: =IF(MAX(F:F)<38,"",IF(INDEX(F:J,MATCH(38,F:F,0),2)=0,"",INDEX(F:J,MATCH(38,F:F,0),2))) | B40: =IF(MAX(F:F)<38,"",INDEX(F:J,MATCH(38,F:F,0),3)) | C40: =IF(MAX(F:F)<38,"",INDEX(F:J,MATCH(38,F:F,0),4)) | D40: =IF(MAX(F:F)<38,"",INDEX(F:J,MATCH(38,F:F,0),5)) | E40: =IF(H40="",E39,E39+1) -> 3 | F40: =IF(E40=E39,"",E40) | G40: =IF(AND(G38="",G39=""),IF(H40="","","Fuel"),"") | H40: =IF('4-Fuel'!$A$23='4-Fuel'!$S$15,"",TEXT('4-Fuel'!$C$23,"#,##0.00")&" Tons "&'4-Fuel'!$A$22&" (Min Cargo: "&TEXT('4-Fuel'!$C$23/100,"#,##0.00")&" Tons)") | J40: ='4-Fuel'!F23 -> 0 | K40: =IF(B40="","",IF(A40="",K39,K39+1))
...

Sheet Profitability
A1: Ship's Expenses | E1: Monthly Report | J1: Variable Report | U1: <<<Edge | AA1: Edge>>>
A3: Mortgage: | B3: ='Ship Info'!B24 -> 25737.5 | E3: =IF(E4<0,"Loss","Profit") -> Loss | G3: Layover (days): | H3: 7 | K3: Time Period (Days): | L3: 14
A4: Maintenance Cost | B4: ='Ship Info'!B25 -> 515 | E4: =H6+H7 -> -45252.5 | G4: Jumps (4 weeks): | H4: =28/(7+H3) -> 2 | K4: Number of Jumps: | L4: 1
A5: Life Support: | B5: ='Ship Info'!B26 -> 0
A6: Crew Salaries: | B6: ='10-Crew'!G32 -> 19000 | G6: Total Income (4 weeks): | H6: =D40*H4 -> 0 | K6: Income: | L6: =L4*D40 -> 0
A7: Fuel: | B7: =IF(E7="No",0,IF(E7="Unrefined",('4-Fuel'!H9*Profitability!H4+('4-Fuel'!H10/'4-Fuel'!C10)*4)*100,(('4-Fuel'!H9+E8+('4-Fuel'!H10/'4-Fuel'!C10)*4)*Profitability!H4)*500)) -> 0 | D7: Buy Fuel? | E7: No | G7: Total Expenses (4 weeks): | H7: =('Ship Info'!B29*-1)-E8 -> -45252.5 | K7: Expenses: | L7: =-1*L3*B8/28 -> -22626.25
A8: Total Expenses: | B8: =SUM(B3:B7) -> 45252.5 | D8: Buy Additional Fuel? | E8: 0 | K8: =IF(L8<0,"Loss:","Profit:") -> Loss: | L8: =L6+L7 -> -22626.25
H9: Listed | J9: Externally Added/Unlisted
B10: Income | E10: Capacity | H10: Cargo from Modules, | J10: Cargo from Modules, | M10: Parsecs
A11: Cargo | B11: Tons | C11: Parsecs | D11: Payments Received | E11: Available | G11: Max | H11: Pods & Carried Ships | J11: Pods & Carried Ships | M11: 0 | N11: 1 | O11: 2 | P11: 3 | Q11: 4 | R11: 5 | S11: 6
A12: Freight | B12: 0 | C12: 0 | D12: =B12*INDEX(M11:S14,2,MATCH(C12,M11:S11,0)) -> 0 | E12: =G12-B12-B13-B14 -> #N/A | F12: of | G12: =IF(C12 > '2-Drives'!D29, 0, ('12-Cargo'!C18 * '12-Cargo'!D18) + ('12-Cargo'!C22 * '12-Cargo'!D22) + ('12-Cargo'!C26 * '12-Cargo'!D26) + '12-Cargo'!D30 + '12-Cargo'!D32 + IF(SUM(B19:B36)=0, '12-Cargo'!C35, 0) + IF(AND(C12 <> '4-Fuel'!B9, '4-Fuel'!B29 > 0), ('4-Fuel'!B9 - C12) * '4-Fuel'!C29, 0) + J12 + H12 + MIN('12-Cargo'!D11 + '12-Cargo'!D13, ABS(HLOOKUP(C12, '2-Drives'!$BC$8:$BT$14, 7, FALSE)) - '1-Hull'!B4) ) -> #N/A | H12: =SUMPRODUCT('9a-Optional'!P27:P56,'9a-Optional'!R27:R56) -> 0 | J12: 0 | L12: Per Ton | M12: 0 | N12: 1000 | O12: 1600 | P12: 2600 | Q12: 4400 | R12: 8500 | S12: 32000
A13: Mail | B13: 0 | C13: 0 | D13: =B13*INDEX(M11:S14,3,MATCH(C13,M11:S11,0)) -> 0 | M13: 0 | N13: 5000 | O13: 5000 | P13: 5000 | Q13: 5000 | R13: 5000 | S13: 5000
A14: Basic/Steerage (2 tons) | B14: 0 | C14: 0 | D14: =B14*INDEX(M11:S14,4,MATCH(C14,M11:S11,0)) -> 0 | M14: 0 | N14: 1000 | O14: 1500 | P14: 2500 | Q14: 4000 | R14: 7000 | S14: 27500
A15: Spec Trade | D15: 0
C16: Total Cargo Income: | D16: =SUM(D12:D15) -> 0 | H16: Listed | J16: Externally Added/Unlisted
E17: Capacity | H17: Staterooms from Modules, | J17: Staterooms from Modules, | M17: Parsecs
A18: Passengers | B18: Staterooms Filled | C18: Parsecs | D18: Payments Received | E18: Available | G18: Max | H18: Pods & Carried Ships | J18: Pods & Carried Ships | M18: 0 | N18: 1 | O18: 2 | P18: 3 | Q18: 4 | R18: 5 | S18: 6
A19: Low Berths | B19: 0 | C19: 0 | D19: =B19*INDEX($M$18:$S$28,2,MATCH(C19,$M$18:$S$18,0)) -> 0 | E19: =G19-B19 -> 0 | F19: of | G19: ='11-Staterooms'!C42+J19+H19 -> 0 | H19: =SUMPRODUCT('9a-Optional'!P27:P56,'9a-Optional'!S27:S56) -> 0 | J19: 0 | L19: Per SR | M19: 0 | N19: 700 | O19: 1300 | P19: 2200 | Q19: 3900 | R19: 7200 | S19: 27000 | T19: 1 low berth
A20: Basic | B20: 0 | C20: 0 | D20: =B20*INDEX($M$18:$S$28,3,MATCH(C20,$M$18:$S$18,0)) -> 0 | E20: =G20-B20-B22 -> 0 | F20: of | G20: ='11-Staterooms'!C46+J20+J22+H20 -> 0 | H20: =SUMPRODUCT('9a-Optional'!P27:P56,'9a-Optional'!T27:T56) -> 0 | J20: 0 | M20: 0 | N20: 4000 | O20: 6000 | P20: 10000 | Q20: 16000 | R20: 28000 | S20: 110000 | T20: (2 sophonts - use 0.5 for a single, or change SR to single occupancy for Middle passage)
A21: Middle Passage | B21: 0 | C21: 0 | D21: =B21*INDEX($M$18:$S$28,4,MATCH(C21,$M$18:$S$18,0)) -> 0 | E21: =G21-B21 -> 0 | F21: of | G21: ='11-Staterooms'!C45+J21+H21 -> 0 | H21: =SUMPRODUCT('9a-Optional'!P27:P56,'9a-Optional'!U27:U56) -> 0 | J21: 0 | M21: 0 | N21: 6500 | O21: 10000 | P21: 14000 | Q21: 23000 | R21: 40000 | S21: 130000 | T21: 1 Middle Passenger
A22: Middle Double Occupancy | B22: 0 | C22: 0 | D22: =B22*INDEX($M$18:$S$28,5,MATCH(C22,$M$18:$S$18,0)) -> 0 | E22: =G20-B20-B22 -> 0 | F22: of | G22: =G20 -> 0 | H22: =SUMPRODUCT('9a-Optional'!P27:P56,'9a-Optional'!V27:V56) -> 0 | J22: 0 | M22: 0 | N22: =1.5*N21 -> 9750 | O22: =1.5*O21 -> 15000 | P22: =1.5*P21 -> 21000 | Q22: =1.5*Q21 -> 34500 | R22: =1.5*R21 -> 60000 | S22: =1.5*S21 -> 195000 | T22: Switch SR to single occupancy for correct fee if not occupied by 2 sophonts
A23: High Passage | B23: 0 | C23: 0 | D23: =B23*INDEX($M$18:$S$28,6,MATCH(C23,$M$18:$S$18,0)) -> 0 | E23: =G23-B23-B25 -> 0 | F23: of | G23: ='11-Staterooms'!C47+J23+J25+H23 -> 0 | H23: =SUMPRODUCT('9a-Optional'!P27:P56,'9a-Optional'!W27:W56) -> 0 | J23: 0 | M23: 0 | N23: 9000 | O23: 14000 | P23: 21000 | Q23: 34000 | R23: 60000 | S23: 210000 | T23: 1 High Passenger
A24: High Double Occupancy | B24: 0 | C24: 0 | D24: =B24*INDEX($M$18:$S$28,7,MATCH(C24,$M$18:$S$18,0)) -> 0 | E24: =G24-B24-B26 -> 0 | F24: of | G24: ='11-Staterooms'!C48+J24+J26+H24 -> 0 | H24: =SUMPRODUCT('9a-Optional'!P27:P56,'9a-Optional'!X27:X56) -> 0 | J24: 0 | M24: 0 | N24: =1.5*N23 -> 13500 | O24: =1.5*O23 -> 21000 | P24: =1.5*P23 -> 31500 | Q24: =1.5*Q23 -> 51000 | R24: =1.5*R23 -> 90000 | S24: =1.5*S23 -> 315000 | T24: Switch SR to single occupancy for correct fee if not occupied by 2 sophonts
A25: Standby Luxury Passage | B25: 0 | C25: 0 | D25: =B25*INDEX($M$18:$S$28,6,MATCH(C25,$M$18:$S$18,0)) -> 0 | E25: =E23 -> 0 | F25: of | G25: =G23 -> 0 | J25: 0 | M25: 0 | N25: 15000 | O25: 20000 | P25: 50000 | Q25: 60000 | R25: 90000 | S25: 320000 | T25: 1 Standby Luxury Passenger
A26: Standby Luxury Double Occupancy | B26: 0 | C26: 0 | D26: =B26*INDEX($M$18:$S$28,7,MATCH(C26,$M$18:$S$18,0)) -> 0 | E26: =E24 -> 0 | F26: of | G26: =G24 -> 0 | J26: 0 | M26: 0 | N26: =1.5*N25 -> 22500 | O26: =1.5*O25 -> 30000 | P26: =1.5*P25 -> 75000 | Q26: =1.5*Q25 -> 90000 | R26: =1.5*R25 -> 135000 | S26: =1.5*S25 -> 480000 | T26: Switch SR to single occupancy for correct fee if not occupied by 2 sophonts
A27: Luxury Passage | B27: 0 | C27: 0 | D27: =B27*INDEX($M$18:$S$28,10,MATCH(C27,$M$18:$S$18,0)) -> 0 | E27: =G27-B27 -> 0 | F27: of | G27: ='11-Staterooms'!C49+J27+H27 -> 0 | H27: =SUMPRODUCT('9a-Optional'!P27:P56,'9a-Optional'!Y27:Y56) -> 0 | J27: 0 | M27: 0 | N27: 36000 | O27: 48000 | P27: 70000 | Q27: 125000 | R27: 200000 | S27: 750000 | T27: 1 Luxury Passenger
A28: Luxury Double Occupancy | B28: 0 | C28: 0 | D28: =B28*INDEX($M$18:$S$28,11,MATCH(C28,$M$18:$S$18,0)) -> 0 | E28: =G28-B28 -> 0 | F28: of | G28: ='11-Staterooms'!C50+J28+H28 -> 0 | H28: =SUMPRODUCT('9a-Optional'!P27:P56,'9a-Optional'!Z27:Z56) -> 0 | J28: 0 | M28: 0 | N28: =1.5*N27 -> 54000 | O28: =1.5*O27 -> 72000 | P28: =1.5*P27 -> 105000 | Q28: =1.5*Q27 -> 187500 | R28: =1.5*R27 -> 300000 | S28: =1.5*S27 -> 1125000 | T28: Switch SR to single occupancy for correct fee if not occupied by 2 sophonts
A29: (SOL) VIP Suite | B29: 0 | C29: 0 | D29: =B29*INDEX($M$18:$S$31,12,MATCH(C29,$M$18:$S$18,0)) -> 0 | E29: =G29-B29 -> 0 | F29: of | G29: ='11-Staterooms'!C51+J29+H29 -> 0 | H29: =SUMPRODUCT('9a-Optional'!P27:P56,'9a-Optional'!AA27:AA56) -> 0 | J29: 0 | M29: 0 | N29: =9000*'11-Staterooms'!M51 -> 36000 | O29: =O23*'11-Staterooms'!M51 -> 56000 | P29: =P23*'11-Staterooms'!M51 -> 84000 | Q29: =Q23*'11-Staterooms'!M51 -> 136000 | R29: =R23*'11-Staterooms'!M51 -> 240000 | S29: =S23*'11-Staterooms'!M51 -> 840000
A30: (SOL) High Passage Block | B30: 0 | C30: 0 | D30: =B30*INDEX($M$18:$S$31,13,MATCH(C30,$M$18:$S$18,0)) -> 0 | E30: =G30-B30 -> 0 | F30: of | G30: ='11-Staterooms'!C52+J30+H30 -> 0 | H30: =SUMPRODUCT('9a-Optional'!P27:P56,'9a-Optional'!AB27:AB56) -> 0 | J30: 0 | M30: 0 | N30: =N23*'11-Staterooms'!$M$52 -> 54000 | O30: =O23*'11-Staterooms'!$M$52 -> 84000 | P30: =P23*'11-Staterooms'!$M$52 -> 126000 | Q30: =Q23*'11-Staterooms'!$M$52 -> 204000 | R30: =R23*'11-Staterooms'!$M$52 -> 360000 | S30: =S23*'11-Staterooms'!$M$52 -> 1260000
A31: (SOL) Steerage Block | B31: 0 | C31: 0 | D31: =B31*INDEX($M$18:$S$31,14,MATCH(C31,$M$18:$S$18,0)) -> 0 | E31: =G31-B31 -> 0 | F31: of | G31: ='11-Staterooms'!C53+J31+H31 -> 0 | H31: =SUMPRODUCT('9a-Optional'!P27:P56,'9a-Optional'!AC27:AC56) -> 0 | J31: 0 | M31: 0 | N31: =N20/2*'11-Staterooms'!$M$53 -> 48000 | O31: =O20/2*'11-Staterooms'!$M$53 -> 72000 | P31: =P20/2*'11-Staterooms'!$M$53 -> 120000 | Q31: =Q20/2*'11-Staterooms'!$M$53 -> 192000 | R31: =R20/2*'11-Staterooms'!$M$53 -> 336000 | S31: =S20/2*'11-Staterooms'!$M$53 -> 1320000 | T31: Use decimals for partially filled Steerage Block
M33: Parsecs
E34: Passengers | G34: Max Passengers | M34: 0 | N34: 1 | O34: 2 | P34: 3 | Q34: 4 | R34: 5 | S34: 6 | T34: Single rates shown. Additional passengers in a single non-basic room add 50%
A35: ='11-Staterooms'!$B$54 | B35: 0 | C35: 1 | D35: =IF(V52=$U$45,MAX(B35,E35)*INDEX(M34:S35,2,MATCH(C35,M34:S34,0)),IF(V52=$U$46,MAX(B35,E35)*INDEX(M34:S35,2,MATCH(C35,M34:S34,0)),IF(E35<B35,B35*INDEX(M34:S35,2,MATCH(C35,M34:S34,0)),(B35+0.5*(E35-B35))*INDEX(M34:S35,2,MATCH(C35,M34:S34,0))))) -> 0 | E35: 0 | G35: =('11-Staterooms'!C54+J35)*'11-Staterooms'!D54 -> 0 | H35: =SUMPRODUCT('9a-Optional'!P27:P56,'9a-Optional'!AD27:AD56) -> 0 | J35: 0 | M35: 0 | N35: =IF(U52>0,U52*INDEX(U44:AA49,MATCH(V52,U44:U49,0),2),INDEX(U37:AA42,MATCH(V52,U37:U42,0),2)) -> 0 | O35: =IF(U52>0,U52*INDEX(U44:AA49,MATCH(V52,U44:U49,0),3),INDEX(U37:AA42,MATCH(V52,U37:U42,0),3)) -> 0 | P35: =IF(U52>0,U52*INDEX(U44:AA49,MATCH(V52,U44:U49,0),4),INDEX(U37:AA42,MATCH(V52,U37:U42,0),4)) -> 0 | Q35: =IF(U52>0,U52*INDEX(U44:AA49,MATCH(V52,U44:U49,0),5),INDEX(U37:AA42,MATCH(V52,U37:U42,0),5)) -> 0 | R35: =IF(U52>0,U52*INDEX(U44:AA49,MATCH(V52,U44:U49,0),6),INDEX(U37:AA42,MATCH(V52,U37:U42,0),6)) -> 0 | S35: =IF(U52>0,U52*INDEX(U44:AA49,MATCH(V52,U44:U49,0),7),INDEX(U37:AA42,MATCH(V52,U37:U42,0),7)) -> 0
A36: ='11-Staterooms'!$B$55 | B36: 0 | C36: 1 | D36: =IF(V52=$U$45,MAX(B36,E36)*INDEX(M34:S36,3,MATCH(C36,M34:S34,0)),IF(V52=$U$46,MAX(B36,E36)*INDEX(M34:S36,3,MATCH(C36,M34:S34,0)),IF(E36<B36,B36*INDEX(M34:S36,3,MATCH(C36,M34:S34,0)),(B36+0.5*(E36-B35))*INDEX(M34:S36,3,MATCH(C35,M34:S34,0))))) -> 0 | E36: 0 | G36: =('11-Staterooms'!C55+J36)*'11-Staterooms'!D55 -> 0 | H36: =SUMPRODUCT('9a-Optional'!P27:P56,'9a-Optional'!AE27:AE56) -> 0 | J36: 0 | M36: 0 | N36: =IF(U53>0,U53*INDEX(U44:AA49,MATCH(V53,U44:U49,0),2),INDEX(U37:AA42,MATCH(V53,U37:U42,0),2)) -> 0 | O36: =IF(U53>0,U53*INDEX(U44:AA49,MATCH(V53,U44:U49,0),3),INDEX(U37:AA42,MATCH(V53,U37:U42,0),3)) -> 0 | P36: =IF(U53>0,U53*INDEX(U44:AA49,MATCH(V53,U44:U49,0),4),INDEX(U37:AA42,MATCH(V53,U37:U42,0),4)) -> 0 | Q36: =IF(U53>0,U53*INDEX(U44:AA49,MATCH(V53,U44:U49,0),5),INDEX(U37:AA42,MATCH(V53,U37:U42,0),5)) -> 0 | R36: =IF(U53>0,U53*INDEX(U44:AA49,MATCH(V53,U44:U49,0),6),INDEX(U37:AA42,MATCH(V53,U37:U42,0),6)) -> 0 | S36: =IF(U53>0,U53*INDEX(U44:AA49,MATCH(V53,U44:U49,0),7),INDEX(U37:AA42,MATCH(V53,U37:U42,0),7)) -> 0 | V36: 1 | W36: 2 | X36: 3 | Y36: 4 | Z36: 5 | AA36: 6
C37: Total Passenger Income: | D37: =SUM(D19:D36) -> 0 | M37: Luxury Passages based on Singularity pricing | U37: ="" | V37: 0 | W37: 0 | X37: 0 | Y37: 0 | Z37: 0 | AA37: 0
M38: Double occupancy adds 50% for second sophont | U38: Low | V38: 700 | W38: 1300 | X38: 2200 | Y38: 3900 | Z38: 7200 | AA38: 27000
J39: This column increases the | U39: Basic | V39: 4000 | W39: 6000 | X39: 10000 | Y39: 16000 | Z39: 28000 | AA39: 110000
C40: Total Income: | D40: =D16+D37 -> 0 | J40: Max for Cargo and Stateroom | U40: Middle | V40: 6500 | W40: 10000 | X40: 14000 | Y40: 23000 | Z40: 40000 | AA40: 130000
J41: Capacity, allowing for situations | U41: High | V41: 9000 | W41: 14000 | X41: 21000 | Y41: 34000 | Z41: 60000 | AA41: 210000
A42: Basic and Middle Double Occupancy share Capacity | J42: not yet handled by the sheet. | U42: Luxury | V42: 36000 | W42: 48000 | X42: 70000 | Y42: 125000 | Z42: 200000 | AA42: 750000
...

Sheet Ship Info
A1: =IF($F$5,"Ship's Class Name",IF($F$6,"Station's Class Name",IF($F$7,"Module's Class Name","Ship's Class Name"))) -> Ship's Class Name | G1: Cost | I1: Available Space | L1: Required Power | S1: No
A2: Class Role | E2: Tech Level: | F2: 12 | G2: =W30*SUM('1-Hull'!F4,'2-Drives'!F5,'3-Pwr Plant'!F5,'4-Fuel'!F5,'5-Bridge'!F5,'6-Comp'!F5,'7-Sensors'!F5,'8a-Weapons'!L5,'8b-Screens'!F5,'9a-Optional'!F5,'9b-Optional'!F5,'11-Staterooms'!F5,'12-Cargo'!F5)*IF(F3="No",1,0.9)+IF('10-Crew'!Q34="Yes",SUM('10-Crew'!S40:T49),0) -> 6177000 | I2: Unused | J2: Max | L2: Unused | M2: Max | S2: Yes
E3: Standard Design? | F3: Yes | G3: First in Class Cost | I3: =ROUND(J3-'1-Hull'!S63-'2-Drives'!S63-'3-Pwr Plant'!S41-'4-Fuel'!S24-'5-Bridge'!S20-'7-Sensors'!S14-'8a-Weapons'!N9-'8b-Screens'!S44-'9a-Optional'!AG29-'9b-Optional'!S10-'11-Staterooms'!S35-'12-Cargo'!S19,2)-IF('1-Hull'!C34="No",'1-Hull'!C32,0) -> 92.53 | J3: ='1-Hull'!I6 -> 100 | L3: =M3-'2-Drives'!S66-'7-Sensors'!S17-'8a-Weapons'!Q9-'8b-Screens'!S47-'1-Hull'!T63-'9a-Optional'!AG32-'9b-Optional'!S13-'11-Staterooms'!S39-'12-Cargo'!S22-'4-Fuel'!S27-'6-Comp'!S101 -> 0 | M3: ='3-Pwr Plant'!L6 -> 20
A4: =IF($F$5,"Ship's Name",IF($F$6,"Station's Name",IF($F$7,"Base Ship's Class Name","Ship's Name"))) -> Ship's Name | F4: =IF(E6="Pod",1,0) -> 0 | G4: =W30*SUM('1-Hull'!F4,'2-Drives'!F5,'3-Pwr Plant'!F5,'4-Fuel'!F5,'5-Bridge'!F5,'6-Comp'!F5,'7-Sensors'!F5,'8a-Weapons'!L5,'8b-Screens'!F5,'9a-Optional'!F5,'9b-Optional'!F5,'11-Staterooms'!F5,'12-Cargo'!F5)*1.01+IF('10-Crew'!Q34="Yes",SUM('10-Crew'!S40:T49),0) -> 6931966.7 | L4: EMER: | M4: ='3-Pwr Plant'!L15
B5: Base Class Usable Hull in Dtons (total with modules): | C5: 1500 | E5: Design is: | F5: =IF(E6="Ship",1,0) -> 1 | L5: BATTERY: | M5: ='3-Pwr Plant'!L18 -> 0 | V5: <<<Edge | X5: Edge>>>
B6: Hardpoints/Firmpoints on Base Class Without Any Modules: | C6: 6 | E6: Ship | F6: =IF(E6="Station",1,0) -> 0 | H6: ="* Is module a fully spaceworthy pod?" -> * Is module a fully spaceworthy pod? | I6: No
A7: Narrative Description | F7: =IF(E6="Module",1,0) -> 0 | G7: Overview
E8: Tab | G8: Cost | H8: Tons | I8: Power | K8: Station | L8: Station Quality Chart
E9: Hull | G9: ='1-Hull'!F4 -> 5000000 | H9: ='1-Hull'!S63 -> 0 | I9: ='1-Hull'!T63 -> 20 | K9: Class
E10: Drives | G10: ='2-Drives'!F5 -> 0 | H10: ='2-Drives'!S63 -> 0 | I10: ='2-Drives'!S66 -> 0 | K10: =IF(K21=5,"*A*","A") -> A
E11: Power Plant | G11: ='3-Pwr Plant'!F5 -> 1333333.3 | H11: ='3-Pwr Plant'!S41 -> 1.3333333 | I11: - | K11: =IF(K21=4,"*B*","B") -> B
E12: Fuel | G12: ='4-Fuel'!F5 -> 0 | H12: ='4-Fuel'!S24 -> 0.13333333 | I12: ='4-Fuel'!S27 -> 0 | K12: =IF(K21=3,"*C*","C") -> C
E13: Bridge | G13: ='5-Bridge'!F5 -> 500000 | H13: ='5-Bridge'!S20 -> 6 | I13: 0 | K13: =IF(K21=2,"*D*","D") -> D
E14: Computer | G14: ='6-Comp'!F5 -> 30000 | H14: 0 | I14: 0 | K14: =IF(K21=1,"*E*","E") -> *E*
E15: Sensors | G15: ='7-Sensors'!F5 -> 0 | H15: ='7-Sensors'!S14 -> 0 | I15: ='7-Sensors'!S17 -> 0 | L15: Sensors | M15: Docking | N15: Refined Fuel/Day | O15: Commercial Zones | P15: Residential Zones | Q15: Shipyard Capacity
E16: Weapons | G16: ='8a-Weapons'!L5 -> 0 | H16: ='8a-Weapons'!N9 -> 0 | I16: ='8a-Weapons'!Q9 -> 0
E17: Screen | G17: ='8b-Screens'!F5 -> 0 | H17: ='8b-Screens'!S44 -> 0 | I17: ='8b-Screens'!S47 -> 0
E18: Optional | G18: ='9a-Optional'!F5+'9b-Optional'!F5 -> 0 | H18: ='9a-Optional'!AG29+'9b-Optional'!S10 -> 0 | I18: ='9a-Optional'!AG32+'9b-Optional'!S13 -> 0
E19: Staterooms | G19: ='11-Staterooms'!F5 -> 0 | H19: ='11-Staterooms'!S35 -> 0 | I19: ='11-Staterooms'!S39 -> 0
E20: Cargo | G20: ='12-Cargo'!F5 -> 0 | H20: ='12-Cargo'!S19 -> 0 | I20: ='12-Cargo'!S22 -> 0
K21: =MIN(L21:Q21) -> 1 | L21: ='7-Sensors'!W41 -> 2 | M21: ='9b-Optional'!T180 -> 1 | N21: ='9b-Optional'!T187 -> 3 | O21: ='9b-Optional'!T177 -> 1 | P21: ='9b-Optional'!T173 -> 2 | Q21: ='9b-Optional'!T194 -> 2
A22: Ship's Expenses | E22: Automation Level: | G22: Standard Automation | V22: New | W22: 1 | X22: 0
G23: Cost Multiplier | H23: Crew Multiplier | P23: Construction Time: | Q23: =TEXT(ROUNDUP((G2/1000000)*(1-(Q25/100))*(1-IF(Tech_Level<12,0,IF(Tech_Level>16,0.5,(Tech_Level-11)*0.1))),0),"#,###")&" Days" -> 6 Days | V23: ="6-10" -> 6-10 | W23: 0.95 | X23: 1
A24: Mortgage: | B24: =IF(C31="Yes",0,IF(S67="No",G2/240,O70/240)) -> 25737.5 | E24: Crew-Intensive | G24: 0.6 | H24: 2 | I24: DM-4 for all shipboard tasks | V24: ="11-15" -> 11-15 | W24: 0.9 | X24: 2
A25: Maintenance Cost | B25: =IF('10-Crew'!Q34="No",ROUND(G2/W30/12/1000,0),ROUND((G2-SUM('10-Crew'!S40:T49))/W30/12/1000,0))+SUM('10-Crew'!AA40:AA49) -> 515 | E25: Low Automation | G25: 0.8 | H25: 1.4 | I25: DM-1 for all shipboard tasks after 1 week in space | P25: Modular Construction %: | Q25: 0 | V25: ="16-25" -> 16-25 | W25: 0.85 | X25: 3
A26: Life Support: | B26: ='11-Staterooms'!F7 -> 0 | E26: Standard Automation | G26: 1 | H26: 1 | I26: ="" | V26: ="26-50" -> 26-50 | W26: 0.8 | X26: 4
A27: Crew Salaries: | B27: ='10-Crew'!G32 -> 19000 | E27: Enhanced Automation | G27: 1.25 | H27: 0.9 | I27: ="" | O27: Construction Time rounded up to whole days | V27: ="51-100" -> 51-100 | W27: 0.75 | X27: 6
A28: Fuel: | B28: =Profitability!B7 -> 0 | E28: Advanced Automation | G28: 1.5 | H28: 0.75 | I28: DM+1 on all shipboard tasks | V28: ="101-250" -> 101-250 | W28: 0.7 | X28: 8
A29: Total Expenses: | B29: =SUM(B24:B28) -> 45252.5 | E29: High Automation | G29: 2 | H29: 0.6 | I29: DM+2 on all shipboard tasks | O29: Outdated/Used Ships | R29: =IF(W30=1,"",(1-W30)*100&"% Discount") | V29: ="251+" -> 251+ | W29: 0.6 | X29: 10
V30: Used: | W30: =INDEX(V22:X29,MATCH(P31,V22:V29,0),2) -> 1 | X30: =INDEX(V22:X29,MATCH(P31,V22:V29,0),3) -> 0
B31: Has the mortgage on this ship been completely paid off? | C31: No | E31: Active labels: | G31: =INDEX(E24:I29,MATCH(G22,E24:E29,0),3) -> 1 | H31: =INDEX(E24:I29,MATCH(G22,E24:E29,0),4) -> 1 | I31: =INDEX(E24:I29,MATCH(G22,E24:E29,0),5) | O31: Age: | P31: New | Q31: =IF(P31="New","","Years Old") | V31: =""
O32: Quirks | V32: Black-listed: DM-1 Broker
B33: Toggle for Section Shading in the Summary Tab is: | C33: On | E33: NOTE: Automation is an optional rule from the Traveller Companion. Standard Automation is HG2022 Compliant | V33: Severely Damaged: -1 Hull
V34: Leaky Reactor Core: Jump on 12, 2Dx20 Rads
B35: Toggle for Unused Space Notification in Summary Tab: | C35: Off | E35: * Making a module fully spaceworthy lets you bypass installing a bridge while having a pod that can survive space on its own. | V35: Well Maintained: 50% Maintenance Costs
B36: Minimum Notification Setpoint: | C36: 0.01 | E36: A Pod can have its own power plant. A Pod can have a bridge or control center other than an SCC, but not under the Main Bridge. | V36: Upgraded Sensors
E37: Instead, these are selected in the Auxilliary Control Room Menu. | V37: Luxurious: DM+1 Steward
A38: =LEFT(A8,C38)&E38 | C38: =IF(MID(A8,D38,1)=" ",D38,IF(MID(A8,D38-1,1)=" ",D38-1,IF(MID(A8,D38-2,1)=" ",D38-2,IF(MID(A8,D38-3,1)=" ",D38-3,IF(MID(A8,D38-4,1)=" ",D38-4,IF(MID(A8,D38-5,1)=" ",D38-5,IF(MID(A8,D38-6,1)=" ",D38-6,IF(MID(A8,D38-7,1)=" ",D38-7,IF(MID(A8,D38-8,1)=" ",D38-8,IF(MID(A8,D38-9,1)=" ",D38-9,IF(MID(A8,D38-10,1)=" ",D38-10,D38-1))))))))))) -> 57 | D38: 58 | E38: =IF(D38>LEN($A$8),"",IF(RIGHT(LEFT($A$8,C38),1)=" ","","-"))
A39: =MID($A$8,C38+1,C39-C38)&E39 | C39: =IF(MID($A$8,D39,1)=" ",D39,IF(MID($A$8,D39-1,1)=" ",D39-1,IF(MID($A$8,D39-2,1)=" ",D39-2,IF(MID($A$8,D39-3,1)=" ",D39-3,IF(MID($A$8,D39-4,1)=" ",D39-4,IF(MID($A$8,D39-5,1)=" ",D39-5,IF(MID($A$8,D39-6,1)=" ",D39-6,IF(MID($A$8,D39-7,1)=" ",D39-7,IF(MID($A$8,D39-8,1)=" ",D39-8,IF(MID($A$8,D39-9,1)=" ",D39-9,IF(MID($A$8,D39-10,1)=" ",D39-10,D39-1))))))))))) -> 115 | D39: =$D$38+C38+1 -> 116 | E39: =IF(D39>LEN($A$8),"",IF(RIGHT(LEFT($A$8,C39),1)=" ","","-"))
A40: =MID($A$8,C39+1,C40-C39)&E40 | C40: =IF(MID($A$8,D40,1)=" ",D40,IF(MID($A$8,D40-1,1)=" ",D40-1,IF(MID($A$8,D40-2,1)=" ",D40-2,IF(MID($A$8,D40-3,1)=" ",D40-3,IF(MID($A$8,D40-4,1)=" ",D40-4,IF(MID($A$8,D40-5,1)=" ",D40-5,IF(MID($A$8,D40-6,1)=" ",D40-6,IF(MID($A$8,D40-7,1)=" ",D40-7,IF(MID($A$8,D40-8,1)=" ",D40-8,IF(MID($A$8,D40-9,1)=" ",D40-9,IF(MID($A$8,D40-10,1)=" ",D40-10,D40-1))))))))))) -> 173 | D40: =$D$38+C39+1 -> 174 | E40: =IF(D40>LEN($A$8),"",IF(RIGHT(LEFT($A$8,C40),1)=" ","","-"))
...

Sheet 1-Hull
A1: ='Ship Info'!A1 -> Ship's Class Name | B1: ='Ship Info'!B1 -> 0 | F1: Cost | S1: Hull Configuration | T1: Streamlined? | U1: Hull Points | V1: Cost | W1: Space | X1: Armor | Y1: ArmSpc | Z1: solar | AA1: Description | AE1: Edge>>>
A2: Class Role | B2: ='Ship Info'!B2 -> 0 | D2: Tech Level: | E2: ='Ship Info'!F2 -> 12 | F2: ='Ship Info'!G2 -> 6177000 | S2: Buffered Planetoid | T2: Unstreamlined | U2: 1.5 | V2: 0.08 | W2: 0.65 | X2: 4 | Y2: 1 | Z2: 0 | AA2: 5 | AC2: value | AD2: Test
B3: ='Ship Info'!G22&" - Costs x "&'Ship Info'!G31 -> Standard Automation - Costs x 1 | F3: Page Totals | H3: =S63 -> 0 | K3: =T63 -> 20 | S3: Close Structure | T3: Partial | U3: 1 | V3: 0.8 | W3: 1 | X3: =IF($A$21=$S$42,4,0) -> 0 | Y3: 1.5 | Z3: 0.5 | AA3: 4 | AB3: TL | AC3: =E10 -> 0 | AD3: =IF(AC3>E2,1,0) -> 0
A4: Tonnage | B4: 100 | F4: =SUM(F6:F50) -> 5000000 | H4: Available Space | K4: Required Power | S4: Dispersed Structure | T4: Unstreamlined | U4: 0.9 | V4: 0.5 | W4: 1 | X4: 0 | Y4: 2 | Z4: 0.5 | AA4: 2 | AB4: Max Armor | AC4: =D10 -> 0 | AD4: =IF(AC4>INDEX(S18:W22,MATCH(B10,S18:S22,0),5),1,0) -> 0
C5: Artificial Gravity (Standard)? | D5: Yes | H5: Unused | I5: Max | K5: Unused | L5: Max | S5: Planetoid | T5: Unstreamlined | U5: 1.25 | V5: 0.08 | W5: 0.8 | X5: 2 | Y5: 1 | Z5: 0 | AA5: 5 | AB5: TL 2ry | AC5: =E40 -> 0
A6: Hull Configuration | B6: Standard | C6: Hull Type | D6: Standard Hull | F6: =IF(AND(D5=D37,B6=D38,D6=D39),B4*IF(AND('Ship Info'!F7=1,'Ship Info'!I6="No"),25000,Y14*(INDEX(S2:Y8,MATCH(B6,S2:S8,0),4))*(INDEX(S13:U15,MATCH(D6,S13:S15,0),3))),(B4-C36)*IF(AND('Ship Info'!F7=1,'Ship Info'!I6="No"),25000,Y14*(INDEX(S2:Y8,MATCH(B6,S2:S8,0),4))*(INDEX(S13:U15,MATCH(D6,S13:S15,0),3)))+C36*IF(AND('Ship Info'!F7=1,'Ship Info'!I6="No"),25000,Z14*(INDEX(S2:Y8,MATCH(D38,S2:S8,0),4))*(INDEX(S13:U15,MATCH(D39,S13:S15,0),3))))*'Ship Info'!G31 -> 5000000 | H6: ='Ship Info'!I3 -> 92.53 | I6: =IF('Ship Info'!F7,Tonnage,Tonnage*INDEX(S2:W11,MATCH(B6,S2:S11,0),5)) -> 100 | K6: ='Ship Info'!L3 -> 0 | L6: ='3-Pwr Plant'!L6 -> 20 | S6: Sphere | T6: Partial | U6: 1 | V6: 1.1 | W6: 1 | X6: =IF($A$21=$S$42,4,0) -> 0 | Y6: 0.9 | Z6: 1 | AA6: 3 | AB6: Max Armor 2ry | AC6: =D41 -> 0
A7: Hull Description | C7: Hull Points | D7: =IF(C36=0,INT(B4/IF(B4>99999.9,1.5,IF(B4>24999.9,2,2.5))*INDEX(S2:U8,MATCH(B6,S2:S8,0),3)*INDEX(S13:T15,MATCH(D6,S13:S15,0),2)),INT((B4-C36)/IF((B4-C36)>99999.9,1.5,IF((B4-C36)>24999.9,2,2.5))*INDEX(S2:U8,MATCH(B6,S2:S8,0),3)*INDEX(S13:T15,MATCH(D6,S13:S15,0),2))+INT(C36/IF(B4>99999.9,1.5,IF(C36>24999.9,2,2.5))*INDEX(S2:U8,MATCH(D38,S2:S8,0),3)*INDEX(S13:T15,MATCH(D39,S13:S15,0),2))) -> 40 | E7: TL | S7: Standard | T7: Partial | U7: 1 | V7: 1 | W7: 1 | X7: =IF($A$21=$S$42,4,0) -> 0 | Y7: 1 | Z7: 1 | AA7: 4 | AB7: Error | AD7: =SUM(AD3:AD6) -> 0
A8: Streamlined? | B8: =INDEX(S2:T11,MATCH(B6,S2:S11,0),2) -> Partial | S8: Streamlined | T8: Streamlined | U8: 1 | V8: 1.2 | W8: 1 | X8: =IF($A$21=$S$42,4,0) -> 0 | Y8: 1.2 | Z8: 0 | AA8: 1
B9: Military Hull: | C9: No | F9: =IF(C9=W13,0,0.25*B4*Y14)*'Ship Info'!G31 -> 0 | H9: Item Tons
A10: Armor Type | B10: No Armor | C10: Armor Value | D10: 0 | E10: =INDEX(S18:V22,MATCH(B10,S18:S22,0),4) -> 0 | F10: =(INDEX(S18:U22,MATCH(B10,S18:S22,0),3)*AB17+INDEX(S18:U22,MATCH(D40,S18:S22,0),3)*AB18)*'Ship Info'!G31 -> 0 | H10: =INDEX(S18:T22,MATCH(B10,S18:S22,0),2)*(B4-C36)*(D11-Z17)*INDEX(S2:Y8,MATCH(B6,S2:S8,0),7)*FtrArmr+IF(C36=0,0,INDEX(S18:T22,MATCH(D40,S18:S22,0),2)*(C36)*(G41-Z18)*INDEX(S2:Y8,MATCH(D38,S2:S8,0),7)*AA18) -> 0
B11: =IF(E2>15,"Molecular Bonded available",IF(E2>13,"Bonded Superdense available",IF(E2>9,"Crystaliron Available",IF(E2>6,"Titanium Steel available","No Armor available")))) -> Crystaliron Available | C11: Armor Total: | D11: =IF(D10=0,Z17,IF(AC4+Z17>Y17,Y17,AC4+Z17)) -> 0 | J11: Basic Ops: | K11: =IF('Ship Info'!E6="Module",0,0.2*B4*T16) -> 20
C12: ="Max Armor = "&Y17 -> Max Armor = 0 | S12: Hull Type | T12: Hull Points | U12: Cost | Z12: =INDEX(S2:Z8,MATCH(B6,S2:S8,0),8) -> 1 | AA12: < Check hull config for solar
A13: Hull Options (Total Hull) | D13: Breakaway Secondary Hull Only | S13: Light Hull | T13: 0.9 | U13: 0.75 | W13: No | X13: 25000 | Z13: 2ry | AC13: =IF(AND(L33="No",U77=1),S15,S13) -> Light Hull
A14: None | B14: =IF(AND(A14=S25,D14=S26),"2ry Hull: "&INDEX($S$25:$AC$26,MATCH(D14,$S$25:$S$26,0),9),INDEX($S$25:$AC$26,MATCH(A14,$S$25:$S$26,0),9)) -> Aerofins | D14: None | E14: =MAX(INDEX($S$25:$AC$26,MATCH(A14,$S$25:$S$26,0),6),INDEX($S$25:$AC$26,MATCH(D14,$S$25:$S$26,0),6)) -> 0 | F14: =MAX(INDEX($S$25:$AC$26,MATCH(A14,$S$25:$S$26,0),3),INDEX($S$25:$AC$26,MATCH(D14,$S$25:$S$26,0),5))*'Ship Info'!G31 -> 0 | H14: =MAX(INDEX($S$25:$AC$26,MATCH(A14,$S$25:$S$26,0),2),INDEX($S$25:$AC$26,MATCH(D14,$S$25:$S$26,0),4)) -> 0 | K14: =INDEX($S$25:$AC$26,MATCH(A14,$S$25:$S$26,0),7) -> 0 | S14: Reinforced Hull | T14: 1.1 | U14: 1.5 | W14: Yes | X14: 50000 | Y14: =INDEX(W13:X14,MATCH(D5,W13:W14,0),2) -> 50000 | Z14: =INDEX(W13:X14,MATCH(D37,W13:W14,0),2) -> 50000 | AC14: =IF(AND(L33="No",U77=1),S15,S14) -> Reinforced Hull
A15: None | B15: =IF(AND(A15=S27,D15=S28),"2ry Hull: "&INDEX($S$27:$AC$28,MATCH(D15,$S$27:$S$28,0),9),INDEX($S$27:$AC$28,MATCH(A15,$S$27:$S$28,0),9)) -> Reflec | D15: None | E15: =MAX(INDEX($S$27:$AC$28,MATCH(A15,$S$27:$S$28,0),6),INDEX($S$27:$AC$28,MATCH(D15,$S$27:$S$28,0),6)) -> 0 | F15: =MAX(INDEX($S$27:$AC$28,MATCH(A15,$S$27:$S$28,0),3),INDEX($S$27:$AC$28,MATCH(D15,$S$27:$S$28,0),5))*'Ship Info'!G31 -> 0 | H15: =MAX(INDEX($S$27:$AC$28,MATCH(A15,$S$27:$S$28,0),2),INDEX($S$27:$AC$28,MATCH(D15,$S$27:$S$28,0),4)) -> 0 | K15: =INDEX($S$27:$AC$28,MATCH(A15,$S$27:$S$28,0),7) -> 0 | S15: Standard Hull | T15: 1 | U15: 1 | Z15: CfgArmr | AA15: FtrArmr | AC15: =S15 -> Standard Hull
A16: None | B16: =IF(AND(A16=S29,D16<>S29),"2ry Hull: "&INDEX($S$29:$AC$30,MATCH(D16,$S$29:$S$30,0),9),INDEX($S$29:$AC$30,MATCH(A16,$S$29:$S$30,0),9)) -> Heat Shielding | D16: None | E16: =MAX(INDEX($S$29:$AC$30,MATCH(A16,$S$29:$S$30,0),6),INDEX($S$29:$AC$30,MATCH(D16,$S$29:$S$30,0),6)) -> 0 | F16: =MAX(INDEX($S$29:$AC$30,MATCH(A16,$S$29:$S$30,0),3),INDEX($S$29:$AC$30,MATCH(D16,$S$29:$S$30,0),5))*'Ship Info'!G31 -> 0 | H16: =MAX(INDEX($S$29:$AC$30,MATCH(A16,$S$29:$S$30,0),2),INDEX($S$29:$AC$30,MATCH(D16,$S$29:$S$30,0),4)) -> 0 | K16: =INDEX($S$29:$AC$30,MATCH(A16,$S$29:$S$30,0),7) -> 0 | S16: Gravity | T16: =IF(D5=W14,1,0.5) -> 1
A17: None | B17: =IF(AND(A17=S48,D17<>S48),"2ry Hull: "&INDEX($S$48:$AC$49,MATCH(D17,$S$48:$S$49,0),9),INDEX($S$48:$AC$49,MATCH(A17,$S$48:$S$49,0),9)) -> Hostile Environment Operations Package | D17: None | E17: =MAX(INDEX($S$48:$AC$49,MATCH(A17,$S$48:$S$49,0),6),INDEX($S$48:$AC$49,MATCH(D17,$S$48:$S$49,0),6)) -> 0 | F17: =(INDEX($S$48:$AC$49,MATCH(A17,$S$48:$S$49,0),3)+IF(INDEX($S$48:$AC$49,MATCH(A17,$S$48:$S$49,0),3)=0,INDEX($S$48:$AC$49,MATCH(D17,$S$48:$S$49,0),5),0))*'Ship Info'!G31 -> 0 | H17: =MAX(INDEX($S$48:$AC$49,MATCH(A17,$S$48:$S$49,0),2),INDEX($S$48:$AC$49,MATCH(D17,$S$48:$S$49,0),4)) -> 0 | K17: =INDEX($S$48:$AC$49,MATCH(A17,$S$48:$S$49,0),7) -> 0 | S17: Armor Type | T17: Tonnage | U17: Cost | V17: TL | W17: Max | X17: =IF('Ship Info'!F7,0,INDEX(S18:V22,MATCH(B10,S18:S22,0),4)) -> 0 | Y17: =IF('Ship Info'!F7,0,INDEX(S18:W22,MATCH(B10,S18:S22,0),5)) -> 0 | Z17: =MAX(INDEX(S2:Y11,MATCH(B6,S2:S11,0),6),IF(AC42,4,0))+X96 -> 0 | AA17: =IF(Tonnage<15.01,4,IF(Tonnage<25.01,3,IF(Tonnage<99.99,2,1))) -> 1 | AB17: =INDEX(S18:T22,MATCH(B10,S18:S22,0),2)*(B4-C36)*(D11-Z17)*INDEX(S2:Y8,MATCH(B6,S2:S8,0),7)*FtrArmr -> 0
